<?xml version='1.0'?>
<sdf version='1.9'><model name='sgcf_diff_drive_robot'><static>false</static>
<link name='base_footprint'/><link name='base_link'><pose relative_to='base_footprint'>0 0 0.1 0 0 0</pose><inertial><mass>20</mass><inertia><ixx>0.5</ixx><iyy>0.8</iyy><izz>1.0</izz></inertia></inertial><collision name='planner_footprint_collision'><geometry><box><size>0.8 0.5 0.2</size></box></geometry><surface><friction><ode><mu>0</mu><mu2>0</mu2></ode></friction></surface></collision><visual name='body'><geometry><box><size>0.8 0.5 0.2</size></box></geometry><material><diffuse>0.15 0.25 0.8 1</diffuse></material></visual></link>
<joint name='base_footprint_to_base_link' type='fixed'><parent>base_footprint</parent><child>base_link</child></joint>
<link name='left_wheel_link'><pose relative_to='base_link'>0 0.25 0 0 0 0</pose><inertial><mass>1</mass><inertia><ixx>0.0027083333333333334</ixx><iyy>0.005</iyy><izz>0.0027083333333333334</izz></inertia></inertial><collision name='left_wheel_collision'><pose>0 -0.025 0 1.5707963267948966 0 0</pose><geometry><cylinder><radius>0.1</radius><length>0.05</length></cylinder></geometry><surface><friction><ode><mu>1</mu><mu2>1</mu2></ode></friction></surface></collision><visual name='left_wheel_visual'><pose>0 -0.025 0 1.5707963267948966 0 0</pose><geometry><cylinder><radius>0.1</radius><length>0.05</length></cylinder></geometry><material><diffuse>0.05 0.05 0.05 1</diffuse></material></visual></link>
<link name='right_wheel_link'><pose relative_to='base_link'>0 -0.25 0 0 0 0</pose><inertial><mass>1</mass><inertia><ixx>0.0027083333333333334</ixx><iyy>0.005</iyy><izz>0.0027083333333333334</izz></inertia></inertial><collision name='right_wheel_collision'><pose>0 0.025 0 1.5707963267948966 0 0</pose><geometry><cylinder><radius>0.1</radius><length>0.05</length></cylinder></geometry><surface><friction><ode><mu>1</mu><mu2>1</mu2></ode></friction></surface></collision><visual name='right_wheel_visual'><pose>0 0.025 0 1.5707963267948966 0 0</pose><geometry><cylinder><radius>0.1</radius><length>0.05</length></cylinder></geometry><material><diffuse>0.05 0.05 0.05 1</diffuse></material></visual></link>
<joint name='left_wheel_joint' type='revolute'><parent>base_link</parent><child>left_wheel_link</child><axis><xyz>0 1 0</xyz><limit><lower>-1e16</lower><upper>1e16</upper><velocity>10</velocity><effort>100</effort></limit></axis></joint>
<joint name='right_wheel_joint' type='revolute'><parent>base_link</parent><child>right_wheel_link</child><axis><xyz>0 1 0</xyz><limit><lower>-1e16</lower><upper>1e16</upper><velocity>10</velocity><effort>100</effort></limit></axis></joint>
<link name='lidar_link'><pose relative_to='base_link'>0 0 0.1 0 0 0</pose><sensor name='lidar' type='gpu_lidar'><always_on>true</always_on><update_rate>10</update_rate><topic>/scan</topic><lidar><scan><horizontal><samples>181</samples><resolution>1</resolution><min_angle>-3.141592653589793</min_angle><max_angle>3.141592653589793</max_angle></horizontal></scan><range><min>0.05</min><max>8.0</max><resolution>0.001</resolution></range><noise><type>gaussian</type><mean>0</mean><stddev>0</stddev></noise></lidar></sensor></link><joint name='lidar_fixed' type='fixed'><parent>base_link</parent><child>lidar_link</child></joint>
<link name='camera_link'><pose relative_to='base_link'>0 0 0.9 0 0 0</pose><sensor name='rgb_camera' type='camera'><always_on>true</always_on><update_rate>10</update_rate><topic>/camera/image_raw</topic><camera><horizontal_fov>1.453284681363431</horizontal_fov><image><width>320</width><height>240</height><format>R8G8B8</format></image><clip><near>0.05</near><far>20</far></clip></camera></sensor></link><joint name='camera_fixed' type='fixed'><parent>base_link</parent><child>camera_link</child></joint>
<frame name='camera_optical_frame' attached_to='camera_link'><pose relative_to='camera_link'>0 0 0 -1.5707963267948966 0 -1.5707963267948966</pose></frame>
<plugin filename='gz-sim-diff-drive-system' name='gz::sim::systems::DiffDrive'><left_joint>left_wheel_joint</left_joint><right_joint>right_wheel_joint</right_joint><wheel_separation>0.5</wheel_separation><wheel_radius>0.1</wheel_radius><odom_publish_frequency>50</odom_publish_frequency><topic>/cmd_vel</topic><odom_topic>/odom</odom_topic><tf_topic>/tf</tf_topic><frame_id>odom</frame_id><child_frame_id>base_link</child_frame_id><max_linear_velocity>1.0</max_linear_velocity><max_angular_velocity>1.5</max_angular_velocity></plugin>
</model></sdf>
